Workbook

Sheet Centres
A1: centre_id | B1: centre_name | C1: handling_capacity_equiv | D1: x_km | E1: y_km
A2: L1 | B2: North Hub | C2: 690 | D2: 20 | E2: 300
A3: L2 | B3: Central Hub | C3: 790 | D3: 65 | E3: 160
A4: L3 | B4: South Hub | C4: 740 | D4: 65 | E4: 15

Sheet Regions
A1: region_id | B1: region_name | C1: severity | D1: x_km | E1: y_km
A2: R1 | B2: North Coast | C2: High | D2: 15 | E2: 270
A3: R2 | B3: North Inland | C3: Medium | D3: 90 | E3: 245
A4: R3 | B4: Central City | C4: Critical | D4: 67 | E4: 200
A5: R4 | B5: East Valley | C5: High | D5: 135 | E5: 115
A6: R5 | B6: South Coast | C6: Medium | D6: 105 | E6: 25
A7: R6 | B7: Mountain District | C7: Critical | D7: 22 | E7: 80

Sheet Resources
A1: resource_id | B1: resource_name | C1: unit | D1: handling_equiv_per_unit | E1: transport_rate_eur_per_unit_km
A2: K1 | B2: Drinking water | C2: case | D2: 1 | E2: 0.019
A3: K2 | B3: Food parcels | C3: parcel | D3: 1.2 | E3: 0.022
A4: K3 | B4: Medical kits | C4: kit | D4: 0.6 | E4: 0.017
A5: K4 | B5: Shelter kits | C5: kit | D5: 3 | E5: 0.032
A6: K5 | B6: Hygiene kits | C6: kit | D6: 0.8 | E6: 0.02

Sheet Supply
A1: centre_id | B1: resource_id | C1: available_units
A2: L1 | B2: K1 | C2: 230
A3: L1 | B3: K2 | C3: 160
A4: L1 | B4: K3 | C4: 65
A5: L1 | B5: K4 | C5: 54
A6: L1 | B6: K5 | C6: 132
A7: L2 | B7: K1 | C7: 230
A8: L2 | B8: K2 | C8: 200
A9: L2 | B9: K3 | C9: 75
A10: L2 | B10: K4 | C10: 65
A11: L2 | B11: K5 | C11: 155
A12: L3 | B12: K1 | C12: 205
A13: L3 | B13: K2 | C13: 170
... A16: L3 | B16: K5 | C16: 135

Sheet Demand
A1: region_id | B1: resource_id | C1: minimum_units
A2: R1 | B2: K1 | C2: 110
A3: R1 | B3: K2 | C3: 75
A4: R1 | B4: K3 | C4: 28
A5: R1 | B5: K4 | C5: 24
A6: R1 | B6: K5 | C6: 65
A7: R2 | B7: K1 | C7: 90
A8: R2 | B8: K2 | C8: 65
A9: R2 | B9: K3 | C9: 20
A10: R2 | B10: K4 | C10: 18
A11: R2 | B11: K5 | C11: 50
A12: R3 | B12: K1 | C12: 130
A13: R3 | B13: K2 | C13: 105
... A31: R6 | B31: K5 | C31: 80

Sheet Transport Costs
A1: centre_id | B1: region_id | C1: resource_id | D1: distance_km | E1: transport_rate_eur_per_unit_km | F1: cost_eur_per_unit
A2: L1 | B2: R1 | C2: K1 | D2: =#REF! -> #REF! | E2: =Resources!E2 -> 0.019 | F2: =ROUND(D2*E2,2) -> #REF!
A3: L1 | B3: R1 | C3: K2 | D3: =#REF! -> #REF! | E3: =Resources!E3 -> 0.022 | F3: =ROUND(D3*E3,2) -> #REF!
A4: L1 | B4: R1 | C4: K3 | D4: =#REF! -> #REF! | E4: =Resources!E4 -> 0.017 | F4: =ROUND(D4*E4,2) -> #REF!
A5: L1 | B5: R1 | C5: K4 | D5: =#REF! -> #REF! | E5: =Resources!E5 -> 0.032 | F5: =ROUND(D5*E5,2) -> #REF!
A6: L1 | B6: R1 | C6: K5 | D6: =#REF! -> #REF! | E6: =Resources!E6 -> 0.02 | F6: =ROUND(D6*E6,2) -> #REF!
A7: L1 | B7: R2 | C7: K1 | D7: =#REF! -> #REF! | E7: =Resources!E2 -> 0.019 | F7: =ROUND(D7*E7,2) -> #REF!
A8: L1 | B8: R2 | C8: K2 | D8: =#REF! -> #REF! | E8: =Resources!E3 -> 0.022 | F8: =ROUND(D8*E8,2) -> #REF!
A9: L1 | B9: R2 | C9: K3 | D9: =#REF! -> #REF! | E9: =Resources!E4 -> 0.017 | F9: =ROUND(D9*E9,2) -> #REF!
A10: L1 | B10: R2 | C10: K4 | D10: =#REF! -> #REF! | E10: =Resources!E5 -> 0.032 | F10: =ROUND(D10*E10,2) -> #REF!
A11: L1 | B11: R2 | C11: K5 | D11: =#REF! -> #REF! | E11: =Resources!E6 -> 0.02 | F11: =ROUND(D11*E11,2) -> #REF!
A12: L1 | B12: R3 | C12: K1 | D12: =#REF! -> #REF! | E12: =Resources!E2 -> 0.019 | F12: =ROUND(D12*E12,2) -> #REF!
A13: L1 | B13: R3 | C13: K2 | D13: =#REF! -> #REF! | E13: =Resources!E3 -> 0.022 | F13: =ROUND(D13*E13,2) -> #REF!
A14: L1 | B14: R3 | C14: K3 | D14: =#REF! -> #REF! | E14: =Resources!E4 -> 0.017 | F14: =ROUND(D14*E14,2) -> #REF!
A15: L1 | B15: R3 | C15: K4 | D15: =#REF! -> #REF! | E15: =Resources!E5 -> 0.032 | F15: =ROUND(D15*E15,2) -> #REF!
A16: L1 | B16: R3 | C16: K5 | D16: =#REF! -> #REF! | E16: =Resources!E6 -> 0.02 | F16: =ROUND(D16*E16,2) -> #REF!
A17: L1 | B17: R4 | C17: K1 | D17: =#REF! -> #REF! | E17: =Resources!E2 -> 0.019 | F17: =ROUND(D17*E17,2) -> #REF!
A18: L1 | B18: R4 | C18: K2 | D18: =#REF! -> #REF! | E18: =Resources!E3 -> 0.022 | F18: =ROUND(D18*E18,2) -> #REF!
A19: L1 | B19: R4 | C19: K3 | D19: =#REF! -> #REF! | E19: =Resources!E4 -> 0.017 | F19: =ROUND(D19*E19,2) -> #REF!
A20: L1 | B20: R4 | C20: K4 | D20: =#REF! -> #REF! | E20: =Resources!E5 -> 0.032 | F20: =ROUND(D20*E20,2) -> #REF!
A21: L1 | B21: R4 | C21: K5 | D21: =#REF! -> #REF! | E21: =Resources!E6 -> 0.02 | F21: =ROUND(D21*E21,2) -> #REF!
A22: L1 | B22: R5 | C22: K1 | D22: =#REF! -> #REF! | E22: =Resources!E2 -> 0.019 | F22: =ROUND(D22*E22,2) -> #REF!
A23: L1 | B23: R5 | C23: K2 | D23: =#REF! -> #REF! | E23: =Resources!E3 -> 0.022 | F23: =ROUND(D23*E23,2) -> #REF!
A24: L1 | B24: R5 | C24: K3 | D24: =#REF! -> #REF! | E24: =Resources!E4 -> 0.017 | F24: =ROUND(D24*E24,2) -> #REF!
A25: L1 | B25: R5 | C25: K4 | D25: =#REF! -> #REF! | E25: =Resources!E5 -> 0.032 | F25: =ROUND(D25*E25,2) -> #REF!
A26: L1 | B26: R5 | C26: K5 | D26: =#REF! -> #REF! | E26: =Resources!E6 -> 0.02 | F26: =ROUND(D26*E26,2) -> #REF!
A27: L1 | B27: R6 | C27: K1 | D27: =#REF! -> #REF! | E27: =Resources!E2 -> 0.019 | F27: =ROUND(D27*E27,2) -> #REF!
A28: L1 | B28: R6 | C28: K2 | D28: =#REF! -> #REF! | E28: =Resources!E3 -> 0.022 | F28: =ROUND(D28*E28,2) -> #REF!
A29: L1 | B29: R6 | C29: K3 | D29: =#REF! -> #REF! | E29: =Resources!E4 -> 0.017 | F29: =ROUND(D29*E29,2) -> #REF!
A30: L1 | B30: R6 | C30: K4 | D30: =#REF! -> #REF! | E30: =Resources!E5 -> 0.032 | F30: =ROUND(D30*E30,2) -> #REF!
A31: L1 | B31: R6 | C31: K5 | D31: =#REF! -> #REF! | E31: =Resources!E6 -> 0.02 | F31: =ROUND(D31*E31,2) -> #REF!
A32: L2 | B32: R1 | C32: K1 | D32: =#REF! -> #REF! | E32: =Resources!E2 -> 0.019 | F32: =ROUND(D32*E32,2) -> #REF!
A33: L2 | B33: R1 | C33: K2 | D33: =#REF! -> #REF! | E33: =Resources!E3 -> 0.022 | F33: =ROUND(D33*E33,2) -> #REF!
A34: L2 | B34: R1 | C34: K3 | D34: =#REF! -> #REF! | E34: =Resources!E4 -> 0.017 | F34: =ROUND(D34*E34,2) -> #REF!
A35: L2 | B35: R1 | C35: K4 | D35: =#REF! -> #REF! | E35: =Resources!E5 -> 0.032 | F35: =ROUND(D35*E35,2) -> #REF!
A36: L2 | B36: R1 | C36: K5 | D36: =#REF! -> #REF! | E36: =Resources!E6 -> 0.02 | F36: =ROUND(D36*E36,2) -> #REF!
A37: L2 | B37: R2 | C37: K1 | D37: =#REF! -> #REF! | E37: =Resources!E2 -> 0.019 | F37: =ROUND(D37*E37,2) -> #REF!
A38: L2 | B38: R2 | C38: K2 | D38: =#REF! -> #REF! | E38: =Resources!E3 -> 0.022 | F38: =ROUND(D38*E38,2) -> #REF!
A39: L2 | B39: R2 | C39: K3 | D39: =#REF! -> #REF! | E39: =Resources!E4 -> 0.017 | F39: =ROUND(D39*E39,2) -> #REF!
A40: L2 | B40: R2 | C40: K4 | D40: =#REF! -> #REF! | E40: =Resources!E5 -> 0.032 | F40: =ROUND(D40*E40,2) -> #REF!
...

Sheet 2D Map
A1: Synthetic relief network: planar coordinates
A2: Coordinates in kilometres. Origin arbitrary; straight-line distances, not road distances.
A4: Centre | B4: Name | C4: x (km) | D4: y (km)
A5: L1 | B5: North Hub | C5: =Centres!D2 -> 20 | D5: =Centres!E2 -> 300
A6: L2 | B6: Central Hub | C6: =Centres!D3 -> 65 | D6: =Centres!E3 -> 160
A7: L3 | B7: South Hub | C7: =Centres!D4 -> 65 | D7: =Centres!E4 -> 15
A10: Region | B10: Name | C10: x (km) | D10: y (km)
A11: R1 | B11: North Coast | C11: =Regions!D2 -> 15 | D11: =Regions!E2 -> 270
A12: R2 | B12: North Inland | C12: =Regions!D3 -> 90 | D12: =Regions!E3 -> 245
A13: R3 | B13: Central City | C13: =Regions!D4 -> 67 | D13: =Regions!E4 -> 200
A14: R4 | B14: East Valley | C14: =Regions!D5 -> 135 | D14: =Regions!E5 -> 115
A15: R5 | B15: South Coast | C15: =Regions!D6 -> 105 | D15: =Regions!E6 -> 25
A16: R6 | B16: Mountain District | C16: =Regions!D7 -> 22 | D16: =Regions!E7 -> 80
A19: Map note | B19: Plot shows baseline points. Edit inputs in Centres/Regions to change distances and costs.
A21: Coordinates are fictional and independent of real latitude/longitude.
